ERROR:root:Traceback (most recent call last):
  File "C:\Users\akzm0\OneDrive\πŸ≈¡ »≠∏È\CHaser\main_chaser.py", line 160, in main
    if value[Moveto[viewpoint]] != 2:
KeyError: 'None'

